Workbook
Name Slicer_Continent: #N/A

Sheet Data
A1: Serial No. | B1: Country | C1: Continent | D1: Production (Tons) | E1: Production per Person (Kg) | F1: Acreage (Hectare) | G1: Yield (Kg / Hectare) | H1: Filter
A2: 1 | B2: Brazil | C2: South America | D2: 768678382 | E2: 3669 | F2: 10226205 | G2: 75168 | H2: =IF(ISNUMBER(MATCH(List_of_Countries_by_Sugarcane_Production[[#This Row],[Continent]],Analysis!$G$2:$G$7,0)),"Yes","No") -> Yes
A3: 2 | B3: India | C3: Asia | D3: 348448000 | E3: 260721 | F3: 4950000 | G3: 70394 | H3: =IF(ISNUMBER(MATCH(List_of_Countries_by_Sugarcane_Production[[#This Row],[Continent]],Analysis!$G$2:$G$7,0)),"Yes","No") -> Yes
A4: 3 | B4: China | C4: Asia | D4: 123059739 | E4: 88287 | F4: 1675215 | G4: 73459 | H4: =IF(ISNUMBER(MATCH(List_of_Countries_by_Sugarcane_Production[[#This Row],[Continent]],Analysis!$G$2:$G$7,0)),"Yes","No") -> Yes
A5: 4 | B5: Thailand | C5: Asia | D5: 87468496 | E5: 1264 | F5: 1336575 | G5: 65442 | H5: =IF(ISNUMBER(MATCH(List_of_Countries_by_Sugarcane_Production[[#This Row],[Continent]],Analysis!$G$2:$G$7,0)),"Yes","No") -> Yes
A6: 5 | B6: Pakistan | C6: Asia | D6: 65450704 | E6: 324219 | F6: 1130820 | G6: 57879 | H6: =IF(ISNUMBER(MATCH(List_of_Countries_by_Sugarcane_Production[[#This Row],[Continent]],Analysis!$G$2:$G$7,0)),"Yes","No") -> Yes
A7: 6 | B7: Mexico | C7: North America | D7: 56446821 | E7: 452524 | F7: 781054 | G7: 7227 | H7: =IF(ISNUMBER(MATCH(List_of_Countries_by_Sugarcane_Production[[#This Row],[Continent]],Analysis!$G$2:$G$7,0)),"Yes","No") -> Yes
A8: 7 | B8: Colombia | C8: South America | D8: 36951213 | E8: 740075 | F8: 416626 | G8: 88692 | H8: =IF(ISNUMBER(MATCH(List_of_Countries_by_Sugarcane_Production[[#This Row],[Continent]],Analysis!$G$2:$G$7,0)),"Yes","No") -> Yes
A9: 8 | B9: Australia | C9: Australia | D9: 34403004 | E9: 1373 | F9: 447204 | G9: 76929 | H9: =IF(ISNUMBER(MATCH(List_of_Countries_by_Sugarcane_Production[[#This Row],[Continent]],Analysis!$G$2:$G$7,0)),"Yes","No") -> Yes
A10: 9 | B10: Guatemala | C10: North America | D10: 33533403 | E10: 1938 | F10: 25985 | G10: 129049 | H10: =IF(ISNUMBER(MATCH(List_of_Countries_by_Sugarcane_Production[[#This Row],[Continent]],Analysis!$G$2:$G$7,0)),"Yes","No") -> Yes
A11: 10 | B11: United States of America | C11: North America | D11: 29926210 | E11: 91304 | F11: 37053 | G11: 80766 | H11: =IF(ISNUMBER(MATCH(List_of_Countries_by_Sugarcane_Production[[#This Row],[Continent]],Analysis!$G$2:$G$7,0)),"Yes","No") -> Yes
A12: 11 | B12: Indonesia | C12: Asia | D12: 27158830 | E12: 10248 | F12: 472693 | G12: 57456 | H12: =IF(ISNUMBER(MATCH(List_of_Countries_by_Sugarcane_Production[[#This Row],[Continent]],Analysis!$G$2:$G$7,0)),"Yes","No") -> Yes
A13: 12 | B13: Philippines | C13: Asia | D13: 22370546 | E13: 210232 | F13: 410104 | G13: 54548 | H13: =IF(ISNUMBER(MATCH(List_of_Countries_by_Sugarcane_Production[[#This Row],[Continent]],Analysis!$G$2:$G$7,0)),"Yes","No") -> Yes
... A104: 103 | B104: Syria | C104: Asia | D104: 1 | E104: 0 | F104: 0 | G104: 83034 | H104: =IF(ISNUMBER(MATCH(List_of_Countries_by_Sugarcane_Production[[#This Row],[Continent]],Analysis!$G$2:$G$7,0)),"Yes","No") -> Yes

Sheet Analysis
A1: Country | B1: Total Production (Tons) | D1: Country | E1: Total Acreage (Hectare) | G1: Continents
A2: Pakistan | B2: 65450704 | D2: Brazil | E2: 10226205 | G2: Africa
A3: Thailand | B3: 87468496 | D3: India | E3: 4950000 | G3: Asia
A4: China | B4: 123059739 | D4: China | E4: 1675215 | G4: Australia
A5: India | B5: 348448000 | D5: Thailand | E5: 1336575 | G5: Europe
A6: Brazil | B6: 768678382 | D6: Pakistan | E6: 1130820 | G6: North America
A7: Grand Total | B7: 1393105321 | D7: Grand Total | E7: 19318815 | G7: South America
A9: Continent | B9: Total Production (Tons) | C9: Average Yield (Kg / Hectare) | E9: Continents | F9: Total Production of continent(Tons) | G9: percentage of Production (Tons)
A10: South America | B10: 865588126 | C10: 61563 | E10: Africa | F10: 89681525 | G10: 0.047516573
A11: Asia | B11: 721930425 | C11: 46874.88 | E11: Asia | F11: 721930425 | G11: 0.38250531
A12: North America | B12: 173995947 | C12: 49209.227 | E12: Australia | F12: 36177574 | G12: 0.01916821
A13: Africa | B13: 89681525 | C13: 56275.205 | E13: North America | F13: 173995947 | G13: 0.092189457
A14: Australia | B14: 36177574 | C14: 40604.75 | E14: South America | F14: 865588126 | G14: 0.45862045
A15: Europe | B15: 5823 | C15: 65935 | E15: Grand Total | F15: 1887373597 | G15: 1
A16: Grand Total | B16: 1887379420 | C16: 52628.058
A18: Country | B18: Average of Yield (Kg / Hectare)
A19: Malawi | B19: 107630
A20: Peru | B20: 112120
A21: Egypt | B21: 115031
A22: Senegal | B22: 118085
A23: Guatemala | B23: 129049
A24: Grand Total | B24: 116383
A27: Total Production (Tons) | C27: Select All
A28: =IFERROR(IF(Dashboard!$D$7="Select All",SUMIF(Data!H:H,"Yes",Data!D:D),SUMIFS(Data!D:D,Data!B:B,Dashboard!$D$7,Data!H:H,"Yes"))," - ") -> 123059739 | C28: Brazil
C29: India
A30: Total Acreage (Hectare) | C30: China
A31: =IFERROR(IF(Dashboard!$D$7="Select All",SUMIF(Data!H:H,"Yes",Data!F:F),SUMIFS(Data!F:F,Data!B:B,Dashboard!$D$7,Data!H:H,"Yes"))," - ") -> 1675215 | C31: Thailand
C32: Pakistan
A33: Average Yield (Kg/hectare) | C33: Mexico
A34: =IFERROR(IF(Dashboard!$D$7="Select All",AVERAGEIF(Data!H:H,"Yes",Data!G:G),AVERAGEIFS(Data!G:G,Data!B:B,Dashboard!$D$7,Data!H:H,"Yes"))," - ") -> 73459 | C34: Colombia
C35: Australia
A36: Total Countries | C36: Guatemala
A37: 103 | C37: United States of America
C38: Indonesia
C39: Philippines
C40: Argentina
C41: Cuba
C42: Vietnam
C43: Egypt
C44: South Africa
...

Sheet Dashboard
D6: Select Country
D7: China
